Workbook
Name ACTION: #REF!
Name ACTION: #REF!

Sheet Cover
B2: TEST REPORT DOCUMENT
A4: Project Name | B4: BrandHub - AI-Powered Multi-Channel Content Platform | E4: Creator | F4: Trung
A5: Project Code | B5: BRANDHUB | E5: Issue Date | F5: 46300
A6: Document Code | B6: =B5&"_"&"Test Report"&"_"&"v1.0" -> BRANDHUB_Test Report_v1.0 | E6: Version | F6: v1.0
A9: Record of change
A10: Effective Date | B10: Version | C10: Change Item | D10: *A,D,M | E10: Change description | F10: Reference
A11: 46300 | B11: v1.0 | C11: All Document | D11: A | E11: Create document - test report for all FRs | F11: Report5_Unit Test.xls

Sheet Test Cases
D1: TEST CASE LIST
B3: Project Name | D3: BrandHub - AI-Powered Multi-Channel Content Platform
B4: Project Code | D4: BRANDHUB
B5: Test Environment Setup Description | D5: 1. Server: Spring Boot 3 business-service (8081), api-gateway (8080), publisher-service (8083), FastAPI ai-service (8082) 2. Database: PostgreSQL 17, MongoDB Atlas, Redis, ChromaDB, Neo4j 3. Message broker: RabbitMQ 4. Web browser: Chrome (latest)
B8: No | C8: Function Name | D8: Sheet Name | E8: Description | F8: Pre-Condition
B9: 1 | C9: 3.2.1 Sign Up (Email + OTP) | D9: Authentication | E9: Register a new account with email/password/fullName, store hashed password, assign USER role, email a 6-digit OTP | F9: Can connect with server; Email not registered
B10: 2 | C10: 3.2.2 Sign In with Email | D10: Authentication | E10: Authenticate by email/phone identifier + password, check account status, issue JWT access + refresh tokens or 2FA challenge | F10: Can connect with server; Account ACTIVE and email verified
B11: 3 | C11: 3.2.3 Sign In with Google OAuth | D11: Authentication | E11: Handle Google callback: verify state, exchange code, login/create/link user and issue JWT or 2FA token | F11: Can connect with server; OAuth state valid in Redis for GOOGLE
B12: 4 | C12: 3.2.4 Reset Password | D12: Authentication | E12: Consume a one-time reset token and set a new bcrypt password, invalidating older sessions via lastPasswordChange | F12: Can connect with server; Reset token valid in Redis
B13: 5 | C13: 3.2.5 Change Password | D13: Authentication | E13: Change password for the logged-in user after verifying current password and rejecting a same-as-current password | F13: Can connect with server; User has password hash
B14: 6 | C14: 3.2.6 OTP Verification | D14: Authentication | E14: Verify the 6-digit email OTP with expiry check, attempt counter (max lockout) and idempotent already-verified handling | F14: Can connect with server; User registered, email not verified, OTP valid
B15: 7 | C15: 3.2.7 Two-Factor Authentication (TOTP) | D15: Authentication | E15: Verify the 2FA challenge token and TOTP code after password login, with 5-attempt lockout, then issue JWT tokens | F15: Can connect with server; User has 2FA enabled with TOTP secret
B16: 8 | C16: 3.2.8 Sign Out | D16: Authentication | E16: Blacklist access and refresh tokens, write LOGOUT audit log; idempotent for invalid/expired tokens | F16: Can connect with server; User logged in with valid tokens
B17: 9 | C17: 3.2.9 Deactivate Account | D17: Authentication | E17: Deactivate own account after password (or OTP for OAuth-only) re-auth, block if owning active agency, revoke tokens | F17: Can connect with server; User has password, owns no active agency
B18: 10 | C18: 3.3.1 View User Profile | D18: Profile | E18: Return the authenticated user's profile (identity, extended fields, preferences) for the current user | F18: Can connect with server; User exists
B19: 11 | C19: 3.3.2 Update Profile | D19: Profile | E19: Update own profile fields (fullName required, optional fields partial), merging preferences without overwriting other keys | F19: Can connect with server; User exists
B20: 12 | C20: 3.3.3 View Client Profile | D20: Profile | E20: List all client profiles owned by the current user (and fetch one by id with ownership check) | F20: Can connect with server; User owns 1 client profile
... B134: 126 | C134: 3.10.12 Export Report File PDF | D134: Admin | E134: Admin exports a user or revenue report to PDF for a date range; empty data still yields a PDF | F134: Can connect with server; Caller has ADMIN system role

Sheet Test Statistics
B1: TEST STATISTICS
B3: Project Name | C3: BrandHub - AI-Powered Multi-Channel Content Platform | E3: Creator | G3: Trung
B4: Project Code | C4: BRANDHUB | E4: Reviewer/Approver
B5: Document Code | C5: =C4&"_"&"Test Report"&"_"&"v1.0" -> BRANDHUB_Test Report_v1.0 | E5: Issue Date | H5: 46300
B6: Notes | C6: Release 1 includes 9 modules: Authentication, Profile, Agency & Workspace, Media Package, Content & Task, AI Features, Publishing, Billing, Admin
B10: No | C10: Module code | D10: Passed | E10: Failed | F10: Pending | G10: N/A | H10: Number of test cases
B11: 1 | C11: =Authentication!B2 -> Authentication | D11: =Authentication!B6 -> 160 | E11: =Authentication!C6 -> 0 | F11: =Authentication!D6 -> 0 | G11: =Authentication!E6 -> 0 | H11: =Authentication!B4 -> 160
B12: 2 | C12: =Profile!B2 -> Profile | D12: =Profile!B6 -> 71 | E12: =Profile!C6 -> 0 | F12: =Profile!D6 -> 0 | G12: =Profile!E6 -> 0 | H12: =Profile!B4 -> 71
B13: 3 | C13: ='Agency & Workspace'!B2 -> Agency & Workspace | D13: ='Agency & Workspace'!B6 -> 394 | E13: ='Agency & Workspace'!C6 -> 0 | F13: ='Agency & Workspace'!D6 -> 0 | G13: ='Agency & Workspace'!E6 -> 0 | H13: ='Agency & Workspace'!B4 -> 394
B14: 4 | C14: ='Media Package'!B2 -> Media Package | D14: ='Media Package'!B6 -> 73 | E14: ='Media Package'!C6 -> 0 | F14: ='Media Package'!D6 -> 126 | G14: ='Media Package'!E6 -> 0 | H14: ='Media Package'!B4 -> 199
B15: 5 | C15: ='Content & Task'!B2 -> Content & Task | D15: ='Content & Task'!B6 -> 151 | E15: ='Content & Task'!C6 -> 0 | F15: ='Content & Task'!D6 -> 511 | G15: ='Content & Task'!E6 -> 0 | H15: ='Content & Task'!B4 -> 662
B16: 6 | C16: ='AI Features'!B2 -> AI Features | D16: ='AI Features'!B6 -> 122 | E16: ='AI Features'!C6 -> 0 | F16: ='AI Features'!D6 -> 84 | G16: ='AI Features'!E6 -> 0 | H16: ='AI Features'!B4 -> 206
B17: 7 | C17: =Publishing!B2 -> Publishing | D17: =Publishing!B6 -> 81 | E17: =Publishing!C6 -> 0 | F17: =Publishing!D6 -> 215 | G17: =Publishing!E6 -> 0 | H17: =Publishing!B4 -> 296
B18: 8 | C18: =Billing!B2 -> Billing | D18: =Billing!B6 -> 32 | E18: =Billing!C6 -> 0 | F18: =Billing!D6 -> 82 | G18: =Billing!E6 -> 0 | H18: =Billing!B4 -> 114
B19: 9 | C19: =Admin!B2 -> Admin | D19: =Admin!B6 -> 33 | E19: =Admin!C6 -> 0 | F19: =Admin!D6 -> 152 | G19: =Admin!E6 -> 0 | H19: =Admin!B4 -> 185
C21: Sub total | D21: =SUM(D11:D19) -> 1117 | E21: =SUM(E11:E19) -> 0 | F21: =SUM(F11:F19) -> 1170 | G21: =SUM(G11:G19) -> 0 | H21: =SUM(H11:H19) -> 2287
C23: Test coverage | E23: =(D21+E21)*100/(H21-G21) -> 48.841277 | F23: %
C24: Test successful coverage | E24: =D21*100/(H21-G21) -> 48.841277 | F24: %

Sheet Authentication
A2: Feature | B2: Authentication | R2: Passed
A3: Test requirement | B3: Functional test of 3.2.1 Sign Up (Email + OTP); 3.2.2 Sign In with Email; 3.2.3 Sign In with Google OAuth; 3.2.4 Reset Password and 5 more | R3: Failed
A4: Number of TCs | B4: =COUNTA(F12:F1000) -> 160 | R4: Pending
A5: Testing Round | B5: Passed | C5: Failed | D5: Pending | E5: N/A | R5: N/A
A6: Round 1 | B6: =COUNTIF($F$10:$F$998,B$5) -> 160 | C6: =COUNTIF($F$10:$F$998,C$5) -> 0 | D6: =COUNTIF($F$10:$F$998,D$5) -> 0 | E6: =COUNTIF($F$10:$F$998,E$5) -> 0
A7: Round 2 | B7: =COUNTIF($I$10:$I$998,B$5) -> 0 | C7: =COUNTIF($I$10:$I$998,C$5) -> 0 | D7: =COUNTIF($I$10:$I$998,D$5) -> 160 | E7: =COUNTIF($I$10:$I$998,E$5) -> 0
A8: Round 3 | B8: =COUNTIF($L$10:$L$998,B$5) -> 0 | C8: =COUNTIF($L$10:$L$998,C$5) -> 0 | D8: =COUNTIF($L$10:$L$998,D$5) -> 160 | E8: =COUNTIF($L$10:$L$998,E$5) -> 0
A10: Test Case ID | B10: Test Case Description | C10: Test Case Procedure | D10: Expected Results | E10: Pre-conditions | F10: Round 1 | G10: Test date | H10: Tester | I10: Round 2 | J10: Test date | K10: Tester | L10: Round 3 | M10: Test date | N10: Tester | O10: Note
A11: 3.2.1 Sign Up (Email + OTP)
A12: FR3.2.1-01 | B12: [Normal] Sign Up (Email + OTP) with email = new@brandhub.vn, password = Abc@12345, fullName = Nguyen Van A | C12: 1. Prepare the state listed in Pre-conditions. 2. Call AuthServiceImpl.register with: email = new@brandhub.vn; password = Abc@12345; fullName = Nguyen Van A. 3. Check the response / error and the log. | D12: 201 Created - RegisterResponse(userId) Log: OTP email sent to new@brandhub.vn | E12: - Can connect with server - Email not registered | F12: Passed | G12: 46300 | H12: Trung | I12: Pending | L12: Pending
A13: FR3.2.1-02 | B13: [Normal] Sign Up (Email + OTP) with email = Mixed@BrandHub.VN , password = Abc@12345, fullName = Nguyen Van A | C13: 1. Prepare the state listed in Pre-conditions. 2. Call AuthServiceImpl.register with: email = Mixed@BrandHub.VN ; password = Abc@12345; fullName = Nguyen Van A. 3. Check the response / error and the log. | D13: 201 Created - email stored lowercase and trimmed Log: OTP email sent | E13: - Can connect with server - Email not registered | F13: Passed | G13: 46300 | H13: Trung | I13: Pending | L13: Pending
A14: FR3.2.1-03 | B14: [Normal] Sign Up (Email + OTP) with email = new@brandhub.vn, password = Abc@12345, fullName = Tran B | C14: 1. Prepare the state listed in Pre-conditions. 2. Call AuthServiceImpl.register with: email = new@brandhub.vn; password = Abc@12345; fullName = Tran B . 3. Check the response / error and the log. | D14: 201 Created - fullName stored trimmed Log: OTP email sent | E14: - Can connect with server - Email not registered | F14: Passed | G14: 46300 | H14: Trung | I14: Pending | L14: Pending
A15: FR3.2.1-04 | B15: [Normal] Sign Up (Email + OTP) with email = new@brandhub.vn, password = Abc@12345, fullName = Nguyen Van A | C15: 1. Prepare the state listed in Pre-conditions. 2. Call AuthServiceImpl.register with: email = new@brandhub.vn; password = Abc@12345; fullName = Nguyen Van A. 3. Check the response / error and the log. | D15: 201 Created - password saved as bcrypt hash, not plaintext | E15: - Can connect with server - Email not registered | F15: Passed | G15: 46300 | H15: Trung | I15: Pending | L15: Pending
A16: FR3.2.1-05 | B16: [Normal] Sign Up (Email + OTP) with email = new@brandhub.vn, password = Abc@12345, fullName = Nguyen Van A | C16: 1. Prepare the state listed in Pre-conditions. 2. Call AuthServiceImpl.register with: email = new@brandhub.vn; password = Abc@12345; fullName = Nguyen Van A. 3. Check the response / error and the log. | D16: 201 Created - UserSystemRole USER saved, emailVerifiedAt null | E16: - Can connect with server - Email not registered | F16: Passed | G16: 46300 | H16: Trung | I16: Pending | L16: Pending
A17: FR3.2.1-06 | B17: [Normal] Sign Up (Email + OTP) with email = new@brandhub.vn, password = Abc@12345, fullName = Nguyen Van A | C17: 1. Prepare the state listed in Pre-conditions. 2. Call AuthServiceImpl.register with: email = new@brandhub.vn; password = Abc@12345; fullName = Nguyen Van A. 3. Check the response / error and the log. | D17: 201 Created - OTP expiry set to now + 10 minutes | E17: - Can connect with server - Email not registered | F17: Passed | G17: 46300 | H17: Trung | I17: Pending | L17: Pending
A18: FR3.2.1-07 | B18: [Normal] Sign Up (Email + OTP) with email = new@brandhub.vn, password = Abc@12345, fullName = Nguyen Van A | C18: 1. Prepare the state listed in Pre-conditions. 2. Call AuthServiceImpl.register with: email = new@brandhub.vn; password = Abc@12345; fullName = Nguyen Van A. 3. Check the response / error and the log. | D18: 201 Created - unverified user cannot login until OTP verified Log: OTP email sent | E18: - Can connect with server - Email not registered | F18: Passed | G18: 46300 | H18: Trung | I18: Pending | L18: Pending
A19: FR3.2.1-08 | B19: [Boundary] Sign Up (Email + OTP) with email = new@brandhub.vn, password = Abcdef12, fullName = Nguyen Van A | C19: 1. Prepare the state listed in Pre-conditions. 2. Call AuthServiceImpl.register with: email = new@brandhub.vn; password = Abcdef12; fullName = Nguyen Van A. 3. Check the response / error and the log. | D19: 201 Created - password exactly 8 chars with 1 digit accepted Log: OTP email sent | E19: - Can connect with server - Email not registered | F19: Passed | G19: 46300 | H19: Trung | I19: Pending | L19: Pending
A20: FR3.2.1-09 | B20: [Boundary] Sign Up (Email + OTP) with email = new@brandhub.vn, password = Abcdefg1, fullName = N | C20: 1. Prepare the state listed in Pre-conditions. 2. Call AuthServiceImpl.register with: email = new@brandhub.vn; password = Abcdefg1; fullName = N. 3. Check the response / error and the log. | D20: 201 Created - fullName 1 char accepted Log: OTP email sent | E20: - Can connect with server - Email not registered | F20: Passed | G20: 46300 | H20: Trung | I20: Pending | L20: Pending
A21: FR3.2.1-10 | B21: [Boundary] Sign Up (Email + OTP) with email = new@brandhub.vn, password = Abcdef1, fullName = Nguyen Van A | C21: 1. Prepare the state listed in Pre-conditions. 2. Call AuthServiceImpl.register with: email = new@brandhub.vn; password = Abcdef1; fullName = Nguyen Van A. 3. Check the response / error and the log. | D21: Error: VALIDATION_ERROR - Password must be at least 8 characters (7 chars) | E21: - Can connect with server - Email not registered | F21: Passed | G21: 46300 | H21: Trung | I21: Pending | L21: Pending
A22: FR3.2.1-11 | B22: [Abnormal] Sign Up (Email + OTP) with email = new@brandhub.vn, password = Abc@12345, fullName = Nguyen Van A | C22: 1. Prepare the state listed in Pre-conditions. 2. Call AuthServiceImpl.register with: email = new@brandhub.vn; password = Abc@12345; fullName = Nguyen Van A. 3. Check the response / error and the log. | D22: Error: EMAIL_ALREADY_EXISTS - 409 This email is already associated with another account | E22: - Can connect with server - Email already registered | F22: Passed | G22: 46300 | H22: Trung | I22: Pending | L22: Pending
A23: FR3.2.1-12 | B23: [Abnormal] Sign Up (Email + OTP) with email = NEW@BrandHub.vn, password = Abc@12345, fullName = Nguyen Van A | C23: 1. Prepare the state listed in Pre-conditions. 2. Call AuthServiceImpl.register with: email = NEW@BrandHub.vn; password = Abc@12345; fullName = Nguyen Van A. 3. Check the response / error and the log. | D23: Error: EMAIL_ALREADY_EXISTS - case-insensitive duplicate, no new account, no OTP resend | E23: - Can connect with server - Email already registered | F23: Passed | G23: 46300 | H23: Trung | I23: Pending | L23: Pending
... A29: FR3.2.1-18 | B29: [Abnormal] Sign Up (Email + OTP) with email = new@brandhub.vn, password = Abc@12345, fullName = empty | C29: 1. Prepare the state listed in Pre-conditions. 2. Call AuthServiceImpl.register with: email = new@brandhub.vn; password = Abc@12345; fullName = empty. 3. Check the response / error and the log. | D29: Error: VALIDATION_ERROR - fullName must not be blank | E29: - Can connect with server | F29: Passed | G29: 46300 | H29: Trung | I29: Pending | L29: Pending
A30: 3.2.2 Sign In with Email
A31: FR3.2.2-01 | B31: [Normal] Sign In with Email with identifier = user@brandhub.vn, password = Abc@12345 | C31: 1. Prepare the state listed in Pre-conditions. 2. Call AuthServiceImpl.login with: identifier = user@brandhub.vn; password = Abc@12345. 3. Check the response / error and the log. | D31: 200 OK - LoginResponse(accessToken, expiresIn) + refresh token Log: Audit LOGIN saved | E31: - Can connect with server - Account ACTIVE and email verified | F31: Passed | G31: 46300 | H31: Trung | I31: Pending | L31: Pending
A32: FR3.2.2-02 | B32: [Normal] Sign In with Email with identifier = USER@BrandHub.VN, password = Abc@12345 | C32: 1. Prepare the state listed in Pre-conditions. 2. Call AuthServiceImpl.login with: identifier = USER@BrandHub.VN; password = Abc@12345. 3. Check the response / error and the log. | D32: 200 OK - identifier matched case-insensitively Log: Audit LOGIN saved | E32: - Can connect with server - Account ACTIVE and email verified | F32: Passed | G32: 46300 | H32: Trung | I32: Pending | L32: Pending
A33: FR3.2.2-03 | B33: [Normal] Sign In with Email with identifier = +84901234567, password = Abc@12345 | C33: 1. Prepare the state listed in Pre-conditions. 2. Call AuthServiceImpl.login with: identifier = +84901234567; password = Abc@12345. 3. Check the response / error and the log. | D33: 200 OK - login by phone identifier Log: Audit LOGIN saved | E33: - Can connect with server - Account ACTIVE and email verified - Identifier is a linked phone number | F33: Passed | G33: 46300 | H33: Trung | I33: Pending | L33: Pending
A34: FR3.2.2-04 | B34: [Normal] Sign In with Email with identifier = user@brandhub.vn, password = Abc@12345 | C34: 1. Prepare the state listed in Pre-conditions. 2. Call AuthServiceImpl.login with: identifier = user@brandhub.vn; password = Abc@12345. 3. Check the response / error and the log. | D34: 200 OK - lastLoginAt updated | E34: - Can connect with server - Account ACTIVE and email verified | F34: Passed | G34: 46300 | H34: Trung | I34: Pending | L34: Pending
A35: FR3.2.2-05 | B35: [Normal] Sign In with Email with identifier = user@brandhub.vn, password = Abc@12345 | C35: 1. Prepare the state listed in Pre-conditions. 2. Call AuthServiceImpl.login with: identifier = user@brandhub.vn; password = Abc@12345. 3. Check the response / error and the log. | D35: 200 OK - access token contains workspaceId claim | E35: - Can connect with server - Account ACTIVE and email verified - User has active workspace | F35: Passed | G35: 46300 | H35: Trung | I35: Pending | L35: Pending
A36: FR3.2.2-06 | B36: [Normal] Sign In with Email with identifier = admin@brandhub.vn, password = Abc@12345 | C36: 1. Prepare the state listed in Pre-conditions. 2. Call AuthServiceImpl.login with: identifier = admin@brandhub.vn; password = Abc@12345. 3. Check the response / error and the log. | D36: 200 OK - access token role=ADMIN | E36: - Can connect with server - Account ACTIVE and email verified - User has role ADMIN | F36: Passed | G36: 46300 | H36: Trung | I36: Pending | L36: Pending
A37: FR3.2.2-07 | B37: [Normal] Sign In with Email with identifier = user@brandhub.vn, password = Abc@12345 | C37: 1. Prepare the state listed in Pre-conditions. 2. Call AuthServiceImpl.login with: identifier = user@brandhub.vn; password = Abc@12345. 3. Check the response / error and the log. | D37: 200 OK - workspaceId claim null | E37: - Can connect with server - Account ACTIVE and email verified - User has no workspace | F37: Passed | G37: 46300 | H37: Trung | I37: Pending | L37: Pending
A38: FR3.2.2-08 | B38: [Normal] Sign In with Email with identifier = user@brandhub.vn, password = Abc@12345 | C38: 1. Prepare the state listed in Pre-conditions. 2. Call AuthServiceImpl.login with: identifier = user@brandhub.vn; password = Abc@12345. 3. Check the response / error and the log. | D38: 200 OK - LoginResponse.twoFactorChallenge(twoFactorToken), no access token | E38: - Can connect with server - Account ACTIVE and email verified - 2FA enabled for user | F38: Passed | G38: 46300 | H38: Trung | I38: Pending | L38: Pending
A39: FR3.2.2-09 | B39: [Normal] Sign In with Email with identifier = user@brandhub.vn, password = Abc@12345 | C39: 1. Prepare the state listed in Pre-conditions. 2. Call AuthServiceImpl.login with: identifier = user@brandhub.vn; password = Abc@12345. 3. Check the response / error and the log. | D39: 200 OK - refresh token returned with refreshExpirationMs | E39: - Can connect with server - Account ACTIVE and email verified | F39: Passed | G39: 46300 | H39: Trung | I39: Pending | L39: Pending
A40: FR3.2.2-10 | B40: [Boundary] Sign In with Email with identifier = user@brandhub.vn, password = A1234567 | C40: 1. Prepare the state listed in Pre-conditions. 2. Call AuthServiceImpl.login with: identifier = user@brandhub.vn; password = A1234567. 3. Check the response / error and the log. | D40: 200 OK - 8-char password matches | E40: - Can connect with server - Account ACTIVE and email verified | F40: Passed | G40: 46300 | H40: Trung | I40: Pending | L40: Pending
A41: FR3.2.2-11 | B41: [Abnormal] Sign In with Email with identifier = ghost@brandhub.vn, password = Abc@12345 | C41: 1. Prepare the state listed in Pre-conditions. 2. Call AuthServiceImpl.login with: identifier = ghost@brandhub.vn; password = Abc@12345. 3. Check the response / error and the log. | D41: Error: INVALID_CREDENTIALS - 401 Invalid email or password | E41: - Can connect with server - Email not registered | F41: Passed | G41: 46300 | H41: Trung | I41: Pending | L41: Pending
A42: FR3.2.2-12 | B42: [Abnormal] Sign In with Email with identifier = user@brandhub.vn, password = WrongPass1 | C42: 1. Prepare the state listed in Pre-conditions. 2. Call AuthServiceImpl.login with: identifier = user@brandhub.vn; password = WrongPass1. 3. Check the response / error and the log. | D42: Error: INVALID_CREDENTIALS - 401 Invalid email or password | E42: - Can connect with server - Account ACTIVE and email verified | F42: Passed | G42: 46300 | H42: Trung | I42: Pending | L42: Pending
... A48: FR3.2.2-18 | B48: [Abnormal] Sign In with Email with identifier = user@brandhub.vn, password = null | C48: 1. Prepare the state listed in Pre-conditions. 2. Call AuthServiceImpl.login with: identifier = user@brandhub.vn; password = null. 3. Check the response / error and the log. | D48: Error: VALIDATION_ERROR - password must not be blank | E48: - Can connect with server | F48: Passed | G48: 46300 | H48: Trung | I48: Pending | L48: Pending
A49: 3.2.3 Sign In with Google OAuth
A50: FR3.2.3-01 | B50: [Normal] Sign In with Google OAuth with code = valid code, state = valid state | C50: 1. Prepare the state listed in Pre-conditions. 2. Call OAuthService (GoogleOAuthService).handleCallback with: code = valid code; state = valid state. 3. Check the response / error and the log. | D50: 200 OK - CallbackResult(loginResult), access + refresh token issued Log: Audit LOGIN saved | E50: - Can connect with server - OAuth state valid in Redis for GOOGLE - Google account already linked to a user | F50: Passed | G50: 46300 | H50: Trung | I50: Pending | L50: Pending
A51: FR3.2.3-02 | B51: [Normal] Sign In with Google OAuth with code = valid code, state = valid state | C51: 1. Prepare the state listed in Pre-conditions. 2. Call OAuthService (GoogleOAuthService).handleCallback with: code = valid code; state = valid state. 3. Check the response / error and the log. | D51: 200 OK - new OAuth-only user created (emailVerifiedAt set, role USER) and logged in Log: Audit LOGIN saved | E51: - Can connect with server - OAuth state valid in Redis for GOOGLE - No user with Google email | F51: Passed | G51: 46300 | H51: Trung | I51: Pending | L51: Pending
A52: FR3.2.3-03 | B52: [Normal] Sign In with Google OAuth with code = valid code, state = valid state | C52: 1. Prepare the state listed in Pre-conditions. 2. Call OAuthService (GoogleOAuthService).handleCallback with: code = valid code; state = valid state. 3. Check the response / error and the log. | D52: 200 OK - Google provider linked to existing account, logged in Log: Audit LOGIN saved | E52: - Can connect with server - OAuth state valid in Redis for GOOGLE - Existing password user with same email | F52: Passed | G52: 46300 | H52: Trung | I52: Pending | L52: Pending
...

Sheet Profile
A2: Feature | B2: Profile | R2: Passed
A3: Test requirement | B3: Functional test of 3.3.1 View User Profile; 3.3.2 Update Profile; 3.3.3 View Client Profile; 3.3.4 Update Client Profile | R3: Failed
A4: Number of TCs | B4: =COUNTA(F12:F1000) -> 71 | R4: Pending
A5: Testing Round | B5: Passed | C5: Failed | D5: Pending | E5: N/A | R5: N/A
A6: Round 1 | B6: =COUNTIF($F$10:$F$998,B$5) -> 71 | C6: =COUNTIF($F$10:$F$998,C$5) -> 0 | D6: =COUNTIF($F$10:$F$998,D$5) -> 0 | E6: =COUNTIF($F$10:$F$998,E$5) -> 0
A7: Round 2 | B7: =COUNTIF($I$10:$I$998,B$5) -> 0 | C7: =COUNTIF($I$10:$I$998,C$5) -> 0 | D7: =COUNTIF($I$10:$I$998,D$5) -> 71 | E7: =COUNTIF($I$10:$I$998,E$5) -> 0
A8: Round 3 | B8: =COUNTIF($L$10:$L$998,B$5) -> 0 | C8: =COUNTIF($L$10:$L$998,C$5) -> 0 | D8: =COUNTIF($L$10:$L$998,D$5) -> 71 | E8: =COUNTIF($L$10:$L$998,E$5) -> 0
A10: Test Case ID | B10: Test Case Description | C10: Test Case Procedure | D10: Expected Results | E10: Pre-conditions | F10: Round 1 | G10: Test date | H10: Tester | I10: Round 2 | J10: Test date | K10: Tester | L10: Round 3 | M10: Test date | N10: Tester | O10: Note
A11: 3.3.1 View User Profile
A12: FR3.3.1-01 | B12: [Normal] View User Profile with currentUser = valid user id | C12: 1. Prepare the state listed in Pre-conditions. 2. Call UserServiceImpl.getUserProfile with: currentUser = valid user id. 3. Check the response / error and the log. | D12: 200 OK - UserProfileResponse with fullName, email, phone | E12: - Can connect with server - User exists | F12: Passed | G12: 46300 | H12: Trung | I12: Pending | L12: Pending
A13: FR3.3.1-02 | B13: [Normal] View User Profile with currentUser = valid user id | C13: 1. Prepare the state listed in Pre-conditions. 2. Call UserServiceImpl.getUserProfile with: currentUser = valid user id. 3. Check the response / error and the log. | D13: 200 OK - timezone read from preferences | E13: - Can connect with server - User exists - Preferences JSON contains timezone | F13: Passed | G13: 46300 | H13: Trung | I13: Pending | L13: Pending
A14: FR3.3.1-03 | B14: [Normal] View User Profile with currentUser = valid user id | C14: 1. Prepare the state listed in Pre-conditions. 2. Call UserServiceImpl.getUserProfile with: currentUser = valid user id. 3. Check the response / error and the log. | D14: 200 OK - notificationPreferences map returned | E14: - Can connect with server - User exists - Preferences JSON contains notificationPreferences | F14: Passed | G14: 46300 | H14: Trung | I14: Pending | L14: Pending
A15: FR3.3.1-04 | B15: [Normal] View User Profile with currentUser = valid user id | C15: 1. Prepare the state listed in Pre-conditions. 2. Call UserServiceImpl.getUserProfile with: currentUser = valid user id. 3. Check the response / error and the log. | D15: 200 OK - skills and portfolioUrls parsed to lists | E15: - Can connect with server - User exists - Skills and portfolioUrls stored as JSON | F15: Passed | G15: 46300 | H15: Trung | I15: Pending | L15: Pending
A16: FR3.3.1-05 | B16: [Normal] View User Profile with currentUser = valid user id | C16: 1. Prepare the state listed in Pre-conditions. 2. Call UserServiceImpl.getUserProfile with: currentUser = valid user id. 3. Check the response / error and the log. | D16: 200 OK - avatarUrl and bannerUrl returned | E16: - Can connect with server - User exists - Avatar and banner uploaded | F16: Passed | G16: 46300 | H16: Trung | I16: Pending | L16: Pending
A17: FR3.3.1-06 | B17: [Normal] View User Profile with currentUser = valid user id | C17: 1. Prepare the state listed in Pre-conditions. 2. Call UserServiceImpl.getUserProfile with: currentUser = valid user id. 3. Check the response / error and the log. | D17: 200 OK - role included in response | E17: - Can connect with server - User exists - User has system role ADMIN | F17: Passed | G17: 46300 | H17: Trung | I17: Pending | L17: Pending
A18: FR3.3.1-07 | B18: [Normal] View User Profile with currentUser = valid user id | C18: 1. Prepare the state listed in Pre-conditions. 2. Call UserServiceImpl.getUserProfile with: currentUser = valid user id. 3. Check the response / error and the log. | D18: 200 OK - workspace role/permissions included | E18: - Can connect with server - User exists - User in workspace as MANAGER | F18: Passed | G18: 46300 | H18: Trung | I18: Pending | L18: Pending
A19: FR3.3.1-08 | B19: [Normal] View User Profile with currentUser = valid user id | C19: 1. Prepare the state listed in Pre-conditions. 2. Call UserServiceImpl.getUserProfile with: currentUser = valid user id. 3. Check the response / error and the log. | D19: 200 OK - linkedin/facebook/instagram/tiktok URLs returned | E19: - Can connect with server - User exists - Social URLs set | F19: Passed | G19: 46300 | H19: Trung | I19: Pending | L19: Pending
A20: FR3.3.1-09 | B20: [Normal] View User Profile with currentUser = valid user id | C20: 1. Prepare the state listed in Pre-conditions. 2. Call UserServiceImpl.getUserProfile with: currentUser = valid user id. 3. Check the response / error and the log. | D20: 200 OK - response has no passwordHash or totpSecret | E20: - Can connect with server - User exists | F20: Passed | G20: 46300 | H20: Trung | I20: Pending | L20: Pending
A21: FR3.3.1-10 | B21: [Boundary] View User Profile with currentUser = valid user id | C21: 1. Prepare the state listed in Pre-conditions. 2. Call UserServiceImpl.getUserProfile with: currentUser = valid user id. 3. Check the response / error and the log. | D21: 200 OK - default empty preferences, no error | E21: - Can connect with server - User exists - Preferences is null | F21: Passed | G21: 46300 | H21: Trung | I21: Pending | L21: Pending
A22: FR3.3.1-11 | B22: [Boundary] View User Profile with currentUser = valid user id | C22: 1. Prepare the state listed in Pre-conditions. 2. Call UserServiceImpl.getUserProfile with: currentUser = valid user id. 3. Check the response / error and the log. | D22: 200 OK - skills returns empty list | E22: - Can connect with server - User exists - Skills JSON is null/empty | F22: Passed | G22: 46300 | H22: Trung | I22: Pending | L22: Pending
A23: FR3.3.1-12 | B23: [Boundary] View User Profile with currentUser = valid user id | C23: 1. Prepare the state listed in Pre-conditions. 2. Call UserServiceImpl.getUserProfile with: currentUser = valid user id. 3. Check the response / error and the log. | D23: 200 OK - parseStringList falls back to empty list | E23: - Can connect with server - User exists - Skills JSON malformed | F23: Passed | G23: 46300 | H23: Trung | I23: Pending | L23: Pending
... A27: FR3.3.1-16 | B27: [Abnormal] View User Profile with currentUser = expired token | C27: 1. Prepare the state listed in Pre-conditions. 2. Call UserServiceImpl.getUserProfile with: currentUser = expired token. 3. Check the response / error and the log. | D27: Error: TOKEN_EXPIRED - 401 Authentication token has expired | E27: - Can connect with server - Access token expired | F27: Passed | G27: 46300 | H27: Trung | I27: Pending | L27: Pending
A28: 3.3.2 Update Profile
A29: FR3.3.2-01 | B29: [Normal] Update Profile with currentUser = valid user id, fullName = Nguyen Van B, phone = 0901234567 | C29: 1. Prepare the state listed in Pre-conditions. 2. Call UserServiceImpl.updateUserProfile with: currentUser = valid user id; fullName = Nguyen Van B; phone = 0901234567. 3. Check the response / error and the log. | D29: 200 OK - fullName and phone updated, other preferences kept | E29: - Can connect with server - User exists | F29: Passed | G29: 46300 | H29: Trung | I29: Pending | L29: Pending
A30: FR3.3.2-02 | B30: [Normal] Update Profile with currentUser = valid user id, fullName = Nguyen Van B, timezone = Asia/Ho_Chi_Minh | C30: 1. Prepare the state listed in Pre-conditions. 2. Call UserServiceImpl.updateUserProfile with: currentUser = valid user id; fullName = Nguyen Van B; timezone = Asia/Ho_Chi_Minh. 3. Check the response / error and the log. | D30: 200 OK - timezone merged, notificationPreferences preserved | E30: - Can connect with server - User exists - Existing notificationPreferences | F30: Passed | G30: 46300 | H30: Trung | I30: Pending | L30: Pending
A31: FR3.3.2-03 | B31: [Normal] Update Profile with currentUser = valid user id, fullName = Nguyen Van B, notificationPreferences = {email:true} | C31: 1. Prepare the state listed in Pre-conditions. 2. Call UserServiceImpl.updateUserProfile with: currentUser = valid user id; fullName = Nguyen Van B; notificationPreferences = {email:true}. 3. Check the response / error and the log. | D31: 200 OK - notificationPreferences replaced, timezone preserved | E31: - Can connect with server - User exists | F31: Passed | G31: 46300 | H31: Trung | I31: Pending | L31: Pending
A32: FR3.3.2-04 | B32: [Normal] Update Profile with currentUser = valid user id, fullName = Nguyen Van B | C32: 1. Prepare the state listed in Pre-conditions. 2. Call UserServiceImpl.updateUserProfile with: currentUser = valid user id; fullName = Nguyen Van B . 3. Check the response / error and the log. | D32: 200 OK - fullName stored trimmed | E32: - Can connect with server - User exists | F32: Passed | G32: 46300 | H32: Trung | I32: Pending | L32: Pending
A33: FR3.3.2-05 | B33: [Normal] Update Profile with currentUser = valid user id, fullName = Nguyen Van B, phone = null | C33: 1. Prepare the state listed in Pre-conditions. 2. Call UserServiceImpl.updateUserProfile with: currentUser = valid user id; fullName = Nguyen Van B; phone = null. 3. Check the response / error and the log. | D33: 200 OK - null phone leaves old phone unchanged | E33: - Can connect with server - User exists - Existing phone | F33: Passed | G33: 46300 | H33: Trung | I33: Pending | L33: Pending
A34: FR3.3.2-06 | B34: [Normal] Update Profile with currentUser = valid user id, fullName = Nguyen Van B, skills = [Design, Copywriting] | C34: 1. Prepare the state listed in Pre-conditions. 2. Call UserServiceImpl.updateUserProfile with: currentUser = valid user id; fullName = Nguyen Van B; skills = [Design, Copywriting]; portfolioUrls = [https://a.com]. 3. Check the response / error and the log. | D34: 200 OK - skills and portfolioUrls saved as JSON | E34: - Can connect with server - User exists | F34: Passed | G34: 46300 | H34: Trung | I34: Pending | L34: Pending
A35: FR3.3.2-07 | B35: [Normal] Update Profile with currentUser = valid user id, fullName = Nguyen Van B, professionalTitle = Content Lead | C35: 1. Prepare the state listed in Pre-conditions. 2. Call UserServiceImpl.updateUserProfile with: currentUser = valid user id; fullName = Nguyen Van B; professionalTitle = Content Lead; bio = 10 years in media. 3. Check the response / error and the log. | D35: 200 OK - title and bio saved | E35: - Can connect with server - User exists | F35: Passed | G35: 46300 | H35: Trung | I35: Pending | L35: Pending
A36: FR3.3.2-08 | B36: [Normal] Update Profile with currentUser = valid user id, fullName = Nguyen Van B, linkedinUrl = https://linkedin.com/in/b | C36: 1. Prepare the state listed in Pre-conditions. 2. Call UserServiceImpl.updateUserProfile with: currentUser = valid user id; fullName = Nguyen Van B; linkedinUrl = https://linkedin.com/in/b; website = https://b.vn. 3. Check the response / error and the log. | D36: 200 OK - social URLs and website saved | E36: - Can connect with server - User exists | F36: Passed | G36: 46300 | H36: Trung | I36: Pending | L36: Pending
A37: FR3.3.2-09 | B37: [Normal] Update Profile with currentUser = valid user id, fullName = Nguyen Van B, profileVisibility = PUBLIC | C37: 1. Prepare the state listed in Pre-conditions. 2. Call UserServiceImpl.updateUserProfile with: currentUser = valid user id; fullName = Nguyen Van B; profileVisibility = PUBLIC. 3. Check the response / error and the log. | D37: 200 OK - profileVisibility stored in preferences | E37: - Can connect with server - User exists | F37: Passed | G37: 46300 | H37: Trung | I37: Pending | L37: Pending
A38: FR3.3.2-10 | B38: [Normal] Update Profile with currentUser = valid user id, fullName = Nguyen Van B, location = Ha Noi | C38: 1. Prepare the state listed in Pre-conditions. 2. Call UserServiceImpl.updateUserProfile with: currentUser = valid user id; fullName = Nguyen Van B; location = Ha Noi; workingLanguage = vi; yearsOfExperience = 5. 3. Check the response / error and the log. | D38: 200 OK - location, language, experience saved | E38: - Can connect with server - User exists | F38: Passed | G38: 46300 | H38: Trung | I38: Pending | L38: Pending
A39: FR3.3.2-11 | B39: [Normal] Update Profile with currentUser = valid user id, fullName = Nguyen Van B | C39: 1. Prepare the state listed in Pre-conditions. 2. Call UserServiceImpl.updateUserProfile with: currentUser = valid user id; fullName = Nguyen Van B. 3. Check the response / error and the log. | D39: 200 OK - email not in request, email unchanged | E39: - Can connect with server - User exists | F39: Passed | G39: 46300 | H39: Trung | I39: Pending | L39: Pending
A40: FR3.3.2-12 | B40: [Boundary] Update Profile with currentUser = valid user id, fullName = N | C40: 1. Prepare the state listed in Pre-conditions. 2. Call UserServiceImpl.updateUserProfile with: currentUser = valid user id; fullName = N. 3. Check the response / error and the log. | D40: 200 OK - fullName 1 char accepted | E40: - Can connect with server - User exists | F40: Passed | G40: 46300 | H40: Trung | I40: Pending | L40: Pending
... A48: FR3.3.2-20 | B48: [Abnormal] Update Profile with currentUser = valid user id, fullName = Nguyen Van B, timezone = UTC | C48: 1. Prepare the state listed in Pre-conditions. 2. Call UserServiceImpl.updateUserProfile with: currentUser = valid user id; fullName = Nguyen Van B; timezone = UTC. 3. Check the response / error and the log. | D48: Error: INVALID_REQUEST - 400 Invalid request format or parameters | E48: - Can connect with server - User exists - Preferences serialization fails | F48: Passed | G48: 46300 | H48: Trung | I48: Pending | L48: Pending
A49: 3.3.3 View Client Profile
A50: FR3.3.3-01 | B50: [Normal] View Client Profile with currentUser = valid user id | C50: 1. Prepare the state listed in Pre-conditions. 2. Call ClientProfileServiceImpl.listMine with: currentUser = valid user id. 3. Check the response / error and the log. | D50: 200 OK - list with 1 ClientProfileResponse | E50: - Can connect with server - User owns 1 client profile | F50: Passed | G50: 46300 | H50: Trung | I50: Pending | L50: Pending
A51: FR3.3.3-02 | B51: [Normal] View Client Profile with currentUser = valid user id | C51: 1. Prepare the state listed in Pre-conditions. 2. Call ClientProfileServiceImpl.listMine with: currentUser = valid user id. 3. Check the response / error and the log. | D51: 200 OK - list with both profiles, no data mixed | E51: - Can connect with server - User owns 2 client profiles (Nike, Adidas) | F51: Passed | G51: 46300 | H51: Trung | I51: Pending | L51: Pending
A52: FR3.3.3-03 | B52: [Normal] View Client Profile with currentUser = valid user id | C52: 1. Prepare the state listed in Pre-conditions. 2. Call ClientProfileServiceImpl.listMine with: currentUser = valid user id. 3. Check the response / error and the log. | D52: 200 OK - response has no agencyId and no email | E52: - Can connect with server - User owns profiles | F52: Passed | G52: 46300 | H52: Trung | I52: Pending | L52: Pending
...

Sheet Agency & Workspace
A2: Feature | B2: Agency & Workspace | R2: Passed
A3: Test requirement | B3: Functional test of 3.4.1 List Agency; 3.4.2 View Agency Dashboard; 3.4.3 Create Agency; 3.4.4 View Agency Profile and 17 more | R3: Failed
A4: Number of TCs | B4: =COUNTA(F12:F1000) -> 394 | R4: Pending
A5: Testing Round | B5: Passed | C5: Failed | D5: Pending | E5: N/A | R5: N/A
A6: Round 1 | B6: =COUNTIF($F$10:$F$998,B$5) -> 394 | C6: =COUNTIF($F$10:$F$998,C$5) -> 0 | D6: =COUNTIF($F$10:$F$998,D$5) -> 0 | E6: =COUNTIF($F$10:$F$998,E$5) -> 0
A7: Round 2 | B7: =COUNTIF($I$10:$I$998,B$5) -> 0 | C7: =COUNTIF($I$10:$I$998,C$5) -> 0 | D7: =COUNTIF($I$10:$I$998,D$5) -> 394 | E7: =COUNTIF($I$10:$I$998,E$5) -> 0
A8: Round 3 | B8: =COUNTIF($L$10:$L$998,B$5) -> 0 | C8: =COUNTIF($L$10:$L$998,C$5) -> 0 | D8: =COUNTIF($L$10:$L$998,D$5) -> 394 | E8: =COUNTIF($L$10:$L$998,E$5) -> 0
A10: Test Case ID | B10: Test Case Description | C10: Test Case Procedure | D10: Expected Results | E10: Pre-conditions | F10: Round 1 | G10: Test date | H10: Tester | I10: Round 2 | J10: Test date | K10: Tester | L10: Round 3 | M10: Test date | N10: Tester | O10: Note
A11: 3.4.1 List Agency
A12: FR3.4.1-01 | B12: [Normal] List Agency with currentUser = owner user | C12: 1. Prepare the state listed in Pre-conditions. 2. Call AgencyServiceImpl.listMyAgencies with: currentUser = owner user. 3. Check the response / error and the log. | D12: 200 - [AgencyResponse(myRole=OWNER)] | E12: - Can connect with server - User owns 1 active agency | F12: Passed | G12: 46300 | H12: Trung | I12: Pending | L12: Pending
A13: FR3.4.1-02 | B13: [Normal] List Agency with currentUser = member user | C13: 1. Prepare the state listed in Pre-conditions. 2. Call AgencyServiceImpl.listMyAgencies with: currentUser = member user. 3. Check the response / error and the log. | D13: 200 - [AgencyResponse(myRole=role of membership)] | E13: - Can connect with server - User is member of 1 agency | F13: Passed | G13: 46300 | H13: Trung | I13: Pending | L13: Pending
A14: FR3.4.1-03 | B14: [Normal] List Agency with currentUser = mixed user | C14: 1. Prepare the state listed in Pre-conditions. 2. Call AgencyServiceImpl.listMyAgencies with: currentUser = mixed user. 3. Check the response / error and the log. | D14: 200 - 2 AgencyResponse items | E14: - Can connect with server - User owns 1 agency and is member of another | F14: Passed | G14: 46300 | H14: Trung | I14: Pending | L14: Pending
A15: FR3.4.1-04 | B15: [Normal] List Agency with currentUser = owner user | C15: 1. Prepare the state listed in Pre-conditions. 2. Call AgencyServiceImpl.listMyAgencies with: currentUser = owner user. 3. Check the response / error and the log. | D15: 200 - agency listed once (ids deduplicated) | E15: - Can connect with server - User owns agency with owner membership row | F15: Passed | G15: 46300 | H15: Trung | I15: Pending | L15: Pending
A16: FR3.4.1-05 | B16: [Normal] List Agency with currentUser = manager user | C16: 1. Prepare the state listed in Pre-conditions. 2. Call AgencyServiceImpl.listMyAgencies with: currentUser = manager user. 3. Check the response / error and the log. | D16: 200 - [AgencyResponse(myRole=MANAGER)] | E16: - Can connect with server - User is member with role MANAGER | F16: Passed | G16: 46300 | H16: Trung | I16: Pending | L16: Pending
A17: FR3.4.1-06 | B17: [Normal] List Agency with currentUser = staff user | C17: 1. Prepare the state listed in Pre-conditions. 2. Call AgencyServiceImpl.listMyAgencies with: currentUser = staff user. 3. Check the response / error and the log. | D17: 200 - [AgencyResponse(myRole=STAFF)] | E17: - Can connect with server - User is member with role STAFF | F17: Passed | G17: 46300 | H17: Trung | I17: Pending | L17: Pending
A18: FR3.4.1-07 | B18: [Normal] List Agency with currentUser = owner user | C18: 1. Prepare the state listed in Pre-conditions. 2. Call AgencyServiceImpl.listMyAgencies with: currentUser = owner user. 3. Check the response / error and the log. | D18: 200 - 3 AgencyResponse items | E18: - Can connect with server - User owns 3 agencies | F18: Passed | G18: 46300 | H18: Trung | I18: Pending | L18: Pending
A19: FR3.4.1-08 | B19: [Boundary] List Agency with currentUser = new user | C19: 1. Prepare the state listed in Pre-conditions. 2. Call AgencyServiceImpl.listMyAgencies with: currentUser = new user. 3. Check the response / error and the log. | D19: 200 - empty list | E19: - Can connect with server - User has no agency and no membership | F19: Passed | G19: 46300 | H19: Trung | I19: Pending | L19: Pending
A20: FR3.4.1-09 | B20: [Boundary] List Agency with currentUser = owner user | C20: 1. Prepare the state listed in Pre-conditions. 2. Call AgencyServiceImpl.listMyAgencies with: currentUser = owner user. 3. Check the response / error and the log. | D20: 200 - list size 1 | E20: - Can connect with server - User owns exactly 1 agency | F20: Passed | G20: 46300 | H20: Trung | I20: Pending | L20: Pending
A21: FR3.4.1-10 | B21: [Boundary] List Agency with currentUser = owner user | C21: 1. Prepare the state listed in Pre-conditions. 2. Call AgencyServiceImpl.listMyAgencies with: currentUser = owner user. 3. Check the response / error and the log. | D21: 200 - agency included | E21: - Can connect with server - User owns 1 agency, status ACTIVE | F21: Passed | G21: 46300 | H21: Trung | I21: Pending | L21: Pending
A22: FR3.4.1-11 | B22: [Boundary] List Agency with currentUser = member user | C22: 1. Prepare the state listed in Pre-conditions. 2. Call AgencyServiceImpl.listMyAgencies with: currentUser = member user. 3. Check the response / error and the log. | D22: 200 - list size 1 | E22: - Can connect with server - User is member of 1 agency only | F22: Passed | G22: 46300 | H22: Trung | I22: Pending | L22: Pending
A23: FR3.4.1-12 | B23: [Abnormal] List Agency with currentUser = owner user | C23: 1. Prepare the state listed in Pre-conditions. 2. Call AgencyServiceImpl.listMyAgencies with: currentUser = owner user. 3. Check the response / error and the log. | D23: 200 - empty list (soft-deleted filtered) | E23: - Can connect with server - User owns 1 SOFT_DELETED agency only | F23: Passed | G23: 46300 | H23: Trung | I23: Pending | L23: Pending
... A27: FR3.4.1-16 | B27: [Abnormal] List Agency with currentUser = null | C27: 1. Prepare the state listed in Pre-conditions. 2. Call AgencyServiceImpl.listMyAgencies with: currentUser = null. 3. Check the response / error and the log. | D27: Error: 401 UNAUTHORIZED - authentication required | E27: - Can connect with server - Request without valid token | F27: Passed | G27: 46300 | H27: Trung | I27: Pending | L27: Pending
A28: 3.4.2 View Agency Dashboard
A29: FR3.4.2-01 | B29: [Normal] View Agency Dashboard with agencyId = existing id, from = null, to = null | C29: 1. Prepare the state listed in Pre-conditions. 2. Call AgencyServiceImpl.getStats with: agencyId = existing id; from = null; to = null. 3. Check the response / error and the log. | D29: 200 - AgencyStatsResponse with totals, membersByRole, workspacesByIndustry, contentByStatus | E29: - Can connect with server - User is OWNER of agency - Agency has members, workspaces, posts | F29: Passed | G29: 46300 | H29: Trung | I29: Pending | L29: Pending
A30: FR3.4.2-02 | B30: [Normal] View Agency Dashboard with agencyId = existing id, from = null, to = null | C30: 1. Prepare the state listed in Pre-conditions. 2. Call AgencyServiceImpl.getStats with: agencyId = existing id; from = null; to = null. 3. Check the response / error and the log. | D30: 200 - AgencyStatsResponse | E30: - Can connect with server - User is MEMBER of agency (not owner) - Agency has data | F30: Passed | G30: 46300 | H30: Trung | I30: Pending | L30: Pending
A31: FR3.4.2-03 | B31: [Normal] View Agency Dashboard with agencyId = existing id, from = 2026-01-01, to = 2026-06-30 | C31: 1. Prepare the state listed in Pre-conditions. 2. Call AgencyServiceImpl.getStats with: agencyId = existing id; from = 2026-01-01; to = 2026-06-30. 3. Check the response / error and the log. | D31: 200 - stats filtered to date range | E31: - Can connect with server - User is OWNER of agency - Agency has data | F31: Passed | G31: 46300 | H31: Trung | I31: Pending | L31: Pending
A32: FR3.4.2-04 | B32: [Normal] View Agency Dashboard with agencyId = existing id, from = null, to = null | C32: 1. Prepare the state listed in Pre-conditions. 2. Call AgencyServiceImpl.getStats with: agencyId = existing id; from = null; to = null. 3. Check the response / error and the log. | D32: 200 - postsPublishedByMonth grouped yyyy-MM | E32: - Can connect with server - User is OWNER of agency - Agency has PUBLISHED posts | F32: Passed | G32: 46300 | H32: Trung | I32: Pending | L32: Pending
A33: FR3.4.2-05 | B33: [Normal] View Agency Dashboard with agencyId = existing id, from = null, to = null | C33: 1. Prepare the state listed in Pre-conditions. 2. Call AgencyServiceImpl.getStats with: agencyId = existing id; from = null; to = null. 3. Check the response / error and the log. | D33: 200 - memberGrowthByMonth grouped by month | E33: - Can connect with server - User is OWNER of agency - Agency has members joined in different months | F33: Passed | G33: 46300 | H33: Trung | I33: Pending | L33: Pending
A34: FR3.4.2-06 | B34: [Normal] View Agency Dashboard with agencyId = existing id, from = null, to = null | C34: 1. Prepare the state listed in Pre-conditions. 2. Call AgencyServiceImpl.getStats with: agencyId = existing id; from = null; to = null. 3. Check the response / error and the log. | D34: 200 - workspacesByIndustry counts | E34: - Can connect with server - User is OWNER of agency - Agency has workspaces with industry | F34: Passed | G34: 46300 | H34: Trung | I34: Pending | L34: Pending
A35: FR3.4.2-07 | B35: [Boundary] View Agency Dashboard with agencyId = existing id, from = null, to = null | C35: 1. Prepare the state listed in Pre-conditions. 2. Call AgencyServiceImpl.getStats with: agencyId = existing id; from = null; to = null. 3. Check the response / error and the log. | D35: 200 - totalWorkspaces=0, no Mongo query, empty content maps | E35: - Can connect with server - User is OWNER of agency - Agency has no workspaces | F35: Passed | G35: 46300 | H35: Trung | I35: Pending | L35: Pending
A36: FR3.4.2-08 | B36: [Boundary] View Agency Dashboard with agencyId = existing id, from = null, to = null | C36: 1. Prepare the state listed in Pre-conditions. 2. Call AgencyServiceImpl.getStats with: agencyId = existing id; from = null; to = null. 3. Check the response / error and the log. | D36: 200 - totalMembers=1, membersByRole={OWNER:1} | E36: - Can connect with server - User is OWNER of agency - Agency has only the owner member | F36: Passed | G36: 46300 | H36: Trung | I36: Pending | L36: Pending
A37: FR3.4.2-09 | B37: [Boundary] View Agency Dashboard with agencyId = existing id, from = joinedAt date, to = null | C37: 1. Prepare the state listed in Pre-conditions. 2. Call AgencyServiceImpl.getStats with: agencyId = existing id; from = joinedAt date; to = null. 3. Check the response / error and the log. | D37: 200 - member included (inclusive bound) | E37: - Can connect with server - User is OWNER of agency - Member joined exactly on from date | F37: Passed | G37: 46300 | H37: Trung | I37: Pending | L37: Pending
A38: FR3.4.2-10 | B38: [Boundary] View Agency Dashboard with agencyId = existing id, from = null, to = joinedAt date | C38: 1. Prepare the state listed in Pre-conditions. 2. Call AgencyServiceImpl.getStats with: agencyId = existing id; from = null; to = joinedAt date. 3. Check the response / error and the log. | D38: 200 - member included (inclusive bound) | E38: - Can connect with server - User is OWNER of agency - Member joined exactly on to date | F38: Passed | G38: 46300 | H38: Trung | I38: Pending | L38: Pending
A39: FR3.4.2-11 | B39: [Boundary] View Agency Dashboard with agencyId = existing id, from = only from set, to = null | C39: 1. Prepare the state listed in Pre-conditions. 2. Call AgencyServiceImpl.getStats with: agencyId = existing id; from = only from set; to = null. 3. Check the response / error and the log. | D39: 200 - open-ended range filter applied | E39: - Can connect with server - User is OWNER of agency - Agency has data | F39: Passed | G39: 46300 | H39: Trung | I39: Pending | L39: Pending
A40: FR3.4.2-12 | B40: [Abnormal] View Agency Dashboard with agencyId = existing id, from = not-a-date, to = null | C40: 1. Prepare the state listed in Pre-conditions. 2. Call AgencyServiceImpl.getStats with: agencyId = existing id; from = not-a-date; to = null. 3. Check the response / error and the log. | D40: 200 - invalid date ignored, full-range stats | E40: - Can connect with server - User is OWNER of agency - Agency has data | F40: Passed | G40: 46300 | H40: Trung | I40: Pending | L40: Pending
... A44: FR3.4.2-16 | B44: [Abnormal] View Agency Dashboard with agencyId = existing id, from = 2000-01-01, to = 2000-01-31 | C44: 1. Prepare the state listed in Pre-conditions. 2. Call AgencyServiceImpl.getStats with: agencyId = existing id; from = 2000-01-01; to = 2000-01-31. 3. Check the response / error and the log. | D44: 200 - all counts 0, empty maps | E44: - Can connect with server - User is OWNER of agency - Range excludes all data | F44: Passed | G44: 46300 | H44: Trung | I44: Pending | L44: Pending
A45: 3.4.3 Create Agency
A46: FR3.4.3-01 | B46: [Normal] Create Agency with currentUser = authenticated user, name = valid name | C46: 1. Prepare the state listed in Pre-conditions. 2. Call AgencyServiceImpl.createAgency with: currentUser = authenticated user; name = valid name. 3. Check the response / error and the log. | D46: 201 - AgencyResponse(myRole=OWNER), owner membership saved | E46: - Can connect with server - User authenticated | F46: Passed | G46: 46300 | H46: Trung | I46: Pending | L46: Pending
A47: FR3.4.3-02 | B47: [Normal] Create Agency with currentUser = authenticated user, name = valid name, category = valid category | C47: 1. Prepare the state listed in Pre-conditions. 2. Call AgencyServiceImpl.createAgency with: currentUser = authenticated user; name = valid name; category = valid category; companySize = valid size. 3. Check the response / error and the log. | D47: 201 - AgencyResponse with category and size | E47: - Can connect with server - User authenticated | F47: Passed | G47: 46300 | H47: Trung | I47: Pending | L47: Pending
A48: FR3.4.3-03 | B48: [Normal] Create Agency with currentUser = authenticated user, name = valid name, website = https://brandhub.vn | C48: 1. Prepare the state listed in Pre-conditions. 2. Call AgencyServiceImpl.createAgency with: currentUser = authenticated user; name = valid name; website = https://brandhub.vn; phone = valid phone. 3. Check the response / error and the log. | D48: 201 - AgencyResponse with website and phone | E48: - Can connect with server - User authenticated | F48: Passed | G48: 46300 | H48: Trung | I48: Pending | L48: Pending
...

Sheet Media Package
A2: Feature | B2: Media Package | R2: Passed
A3: Test requirement | B3: Functional test of 3.5.1 Create Media Package; 3.5.2 View the Template Media Package; 3.5.3 Request Media Package (Negotiate Terms); 3.5.4 Approve Media Package and 6 more | R3: Failed
A4: Number of TCs | B4: =COUNTA(F12:F1000) -> 199 | R4: Pending
A5: Testing Round | B5: Passed | C5: Failed | D5: Pending | E5: N/A | R5: N/A
A6: Round 1 | B6: =COUNTIF($F$10:$F$998,B$5) -> 73 | C6: =COUNTIF($F$10:$F$998,C$5) -> 0 | D6: =COUNTIF($F$10:$F$998,D$5) -> 126 | E6: =COUNTIF($F$10:$F$998,E$5) -> 0
A7: Round 2 | B7: =COUNTIF($I$10:$I$998,B$5) -> 0 | C7: =COUNTIF($I$10:$I$998,C$5) -> 0 | D7: =COUNTIF($I$10:$I$998,D$5) -> 199 | E7: =COUNTIF($I$10:$I$998,E$5) -> 0
A8: Round 3 | B8: =COUNTIF($L$10:$L$998,B$5) -> 0 | C8: =COUNTIF($L$10:$L$998,C$5) -> 0 | D8: =COUNTIF($L$10:$L$998,D$5) -> 199 | E8: =COUNTIF($L$10:$L$998,E$5) -> 0
A10: Test Case ID | B10: Test Case Description | C10: Test Case Procedure | D10: Expected Results | E10: Pre-conditions | F10: Round 1 | G10: Test date | H10: Tester | I10: Round 2 | J10: Test date | K10: Tester | L10: Round 3 | M10: Test date | N10: Tester | O10: Note
A11: 3.5.1 Create Media Package
A12: FR3.5.1-01 | B12: [Normal] Create Media Package with agencyId = existing agency, name = Starter, type = BY_DURATION | C12: 1. Prepare the state listed in Pre-conditions. 2. Call MediaPackageServiceImpl.createCustomPackage with: agencyId = existing agency; name = Starter; type = BY_DURATION; durationWeeks = 4; budgetAmount = null; sourceTemplateId = null. 3. Check the response / error and the log. | D12: MediaPackageResponse(isTemplate=false, agencyId, availableToWorkspaces=true) Log: Package saved | E12: - Can connect with server - Agency exists - User is OWNER of agency | F12: Passed | G12: 46300 | H12: Lộc | I12: Pending | L12: Pending
A13: FR3.5.1-02 | B13: [Normal] Create Media Package with agencyId = existing agency, name = Budget Pack, type = BY_BUDGET | C13: 1. Prepare the state listed in Pre-conditions. 2. Call MediaPackageServiceImpl.createCustomPackage with: agencyId = existing agency; name = Budget Pack; type = BY_BUDGET; budgetAmount = 5000.00; durationWeeks = null; sourceTemplateId = null. 3. Check the response / error and the log. | D13: MediaPackageResponse(packageType=BY_BUDGET, budgetAmount=5000.00) | E13: - Can connect with server - Agency exists - User is OWNER of agency | F13: Passed | G13: 46300 | H13: Lộc | I13: Pending | L13: Pending
A14: FR3.5.1-03 | B14: [Normal] Create Media Package with agencyId = existing agency, name = Full Pack, type = FULL_DELEGATION | C14: 1. Prepare the state listed in Pre-conditions. 2. Call MediaPackageServiceImpl.createCustomPackage with: agencyId = existing agency; name = Full Pack; type = FULL_DELEGATION; durationWeeks = null; budgetAmount = null; sourceTemplateId = null. 3. Check the response / error and the log. | D14: MediaPackageResponse(packageType=FULL_DELEGATION) | E14: - Can connect with server - Agency exists - User is OWNER of agency | F14: Passed | G14: 46300 | H14: Lộc | I14: Pending | L14: Pending
A15: FR3.5.1-04 | B15: [Normal] Create Media Package with agencyId = existing agency, name = From Template, type = BY_DURATION | C15: 1. Prepare the state listed in Pre-conditions. 2. Call MediaPackageServiceImpl.createCustomPackage with: agencyId = existing agency; name = From Template; type = BY_DURATION; durationWeeks = 8; sourceTemplateId = valid template id. 3. Check the response / error and the log. | D15: MediaPackageResponse(sourceTemplateId set, isTemplate=false) | E15: - Can connect with server - Agency exists - User is OWNER of agency - Source template is a system template | F15: Passed | G15: 46300 | H15: Lộc | I15: Pending | L15: Pending
A16: FR3.5.1-05 | B16: [Normal] Create Media Package with agencyId = existing agency, name = Padded , type = FULL_DELEGATION | C16: 1. Prepare the state listed in Pre-conditions. 2. Call MediaPackageServiceImpl.createCustomPackage with: agencyId = existing agency; name = Padded ; type = FULL_DELEGATION; scopeDescription = scope text . 3. Check the response / error and the log. | D16: name trimmed to 'Padded', scopeDescription trimmed | E16: - Can connect with server - Agency exists - User is OWNER of agency | F16: Passed | G16: 46300 | H16: Lộc | I16: Pending | L16: Pending
A17: FR3.5.1-06 | B17: [Normal] Create Media Package with agencyId = existing agency, name = Blank Scope, type = FULL_DELEGATION | C17: 1. Prepare the state listed in Pre-conditions. 2. Call MediaPackageServiceImpl.createCustomPackage with: agencyId = existing agency; name = Blank Scope; type = FULL_DELEGATION; scopeDescription = blank. 3. Check the response / error and the log. | D17: MediaPackageResponse(scopeDescription=null) | E17: - Can connect with server - Agency exists - User is OWNER of agency | F17: Passed | G17: 46300 | H17: Lộc | I17: Pending | L17: Pending
A18: FR3.5.1-07 | B18: [Normal] Create Media Package with agencyId = existing agency, name = Mgr Pack, type = FULL_DELEGATION | C18: 1. Prepare the state listed in Pre-conditions. 2. Call MediaPackageServiceImpl.createCustomPackage with: agencyId = existing agency; name = Mgr Pack; type = FULL_DELEGATION; workspaceId = workspace of same agency. 3. Check the response / error and the log. | D18: MediaPackageResponse(createdBy=manager id) | E18: - Can connect with server - Agency exists - User is MANAGER of workspace - Workspace belongs to the agency | F18: Passed | G18: 46300 | H18: Lộc | I18: Pending | L18: Pending
A19: FR3.5.1-08 | B19: [Normal] Create Media Package with agencyId = existing agency, name = Owner With Ws, type = FULL_DELEGATION | C19: 1. Prepare the state listed in Pre-conditions. 2. Call MediaPackageServiceImpl.createCustomPackage with: agencyId = existing agency; name = Owner With Ws; type = FULL_DELEGATION; workspaceId = any (ignored). 3. Check the response / error and the log. | D19: Owner path skips workspace check; package created | E19: - Can connect with server - Agency exists - User is OWNER of agency | F19: Passed | G19: 46300 | H19: Lộc | I19: Pending | L19: Pending
